Workbook
Name ADDRESS: XLOOKUP!$C$3:$C$22
Name City: XLOOKUP!$D$3:$D$22
Name DATE: XLOOKUP!$H$3:$H$22
Name DEPT: XLOOKUP!$F$3:$F$22
Name Emp_Code: XLOOKUP!$A$3:$A$22
Name EmpCodeArray: 'complax vlookup'!$A$1:$H$21
Name EmpCodeHeader: 'complax vlookup'!$A$1:$H$1
Name FirstTable: 'Nasted vlookup'!$A$1:$B$16
Name Headcer1: 'Nasted vlookup'!$A$1:$B$1
Name Header: 'SOURCE DATA'!$A$1:$H$1
Name Header2: 'Nasted vlookup'!$F$1:$G$1
Name HeaderArray: 'index & match'!$A$1:$G$1
Name HHeader: HLOOKUP!$A$1:$A$7
Name Htablearray: HLOOKUP!$B$1:$U$7
Name NAME: XLOOKUP!$B$3:$B$22
Name namerange: 'index & match'!$B$1:$B$21
Name NametableArray: 'complax vlookup'!$B$1:$H$21
Name NametableHeader: 'complax vlookup'!$B$1:$H$1
Name Nempcode: Vlookup!$A$3:$A$23
Name NHtablearray: HLOOKUP!$A$1:$U$7
Name REGION: XLOOKUP!$E$3:$E$22
Name SAL: XLOOKUP!$G$3:$G$22
Name SData: 'SOURCE DATA'!$A$1:$H$21
Name SecondTable: 'Nasted vlookup'!$F$1:$G$16
Name TableArray: 'index & match'!$A$1:$G$21
Name USdata: 'SOURCE DATA'!$A$1:$H$22

Sheet INTRO
A1: About Excel
B3: What is Excel ? | H3: MS Office Versions (similarities and differences) & Interface (latest available version)
B5: Microsoft Excel is a powerful spreadsheet software widely used for data
B6: organization, analysis, and visualization. It is part of the Microsoft Office | H6: 1.Microsoft Office 2003
B7: suite and is commonly used for tasks such as budgeting, project | H7: 2. Microsoft Office 2007
B8: management, data analysis, and report generation. | H8: 3. Microsoft Office 2010
H9: 3. Microsoft Office 2013
H10: 3. Microsoft Office 2016
B11: History of Spreadsheet | E11: Founders of Spreadsheet | H11: 3. Microsoft Office 2019
B12: Application Name | C12: Year | E12: Dan Bricklin | H12: 3. Microsoft Office 2021
B13: Visicalc | C13: 1978 | E13: Bob Frankston | H13: 3. Microsoft 365 (formerly Office 365)
B14: SuperCalc | C14: 1980
B15: Lotus 1-2-3 | C15: 1983 | E15: For more info | H15: The main differences between MS Office versions lie in the user interface, cloud integration, collaboration tools,
B16: Multiplan/Excel | C16: 1982/1985 | E16: www.bricklin.com | H16: and the pricing model. For users who need continuous updates and cloud-based features, Microsoft 365 is ideal,
H17: while traditional Office users can rely on Office 2021 or earlier versions for a one-time purchase solution.
B21: What is Row? | C21: A row in a table or spreadsheet is a horizontal line of data, whereas a column in a chart, table, or spreadsheet is a vertical line of cells. | H21: Data Types
B22: What is column?
H23: Excel allows various types of data, including:
B24: What is cell? | C24: a rectangular box in a worksheet that is formed by the intersection of a row and a column
H25: Text: Alphanumeric characters (e.g., names, descriptions).
H27: Numbers: Numeric data used for calculations.
H29: Dates: Used for representing dates and times.
B30: Column | C30: 16384
B31: Row | C31: 1048576 | H31: Formulas: Mathematical expressions that perform calculations using cell values.

Sheet Day 1
A1: Sr.Num | B1: Name | C1: Marks | D1: Grade | E1: Marks | J1: SR.num | L1: Even num | N1: odd num | P1: week Name | Q1: week Name | R1: month Nmae | S1: month Nmae | T1: Custom list
A2: 1 | B2: Kavita | C2: 50 | D2: A | E2: 50 | J2: 1 | L2: 4 | N2: 3 | P2: MON | Q2: Mon | R2: jan | S2: May | T2: A
A3: 2 | B3: Anvi | C3: 20 | D3: B | E3: 20 | F3: Kavita got 50 marks in grade A | J3: 2 | L3: 6 | N3: 5 | P3: TUE | Q3: Tuesday | R3: feb | S3: June | T3: B
A4: 3 | B4: Nirvi | C4: 12 | D4: A | E4: 12 | J4: 3 | L4: 8 | N4: 7 | P4: WED | Q4: Wednesday | R4: mar | S4: July | T4: C
A5: 4 | B5: Priya | C5: 80 | D5: B | E5: 80 | J5: 4 | L5: 10 | N5: 9 | P5: THU | Q5: Thursday | R5: apr | S5: August | T5: D
A6: 5 | B6: Maya | C6: 90 | D6: A | E6: 90 | J6: 5 | L6: 12 | N6: 11 | P6: FRI | Q6: Friday | R6: may | S6: September | T6: E
A7: 6 | B7: Surya | C7: 30 | D7: A | E7: 30 | J7: 6 | L7: 14 | N7: 13 | P7: SAT | Q7: Saturday | R7: jun | S7: October | T7: A
A8: 7 | B8: Rajesh | C8: 50 | D8: A | E8: 50 | J8: 7 | L8: 16 | N8: 15 | P8: SUN | Q8: Sunday | R8: jul | S8: November | T8: B
A9: 8 | B9: Charan | C9: 35 | D9: A | E9: 35 | J9: 8 | L9: 18 | N9: 17 | P9: MON | Q9: Mon | R9: aug | S9: December | T9: C
A10: 9 | B10: Kabir | C10: 40 | D10: B | E10: 40 | J10: 9 | L10: 20 | N10: 19 | P10: TUE | Q10: Tuesday | R10: sep | S10: January | T10: D
A11: 10 | B11: Sriniwas | C11: 80 | D11: C | E11: 80 | J11: 10 | L11: 22 | N11: 21 | P11: WED | Q11: Wednesday | R11: oct | S11: February | T11: E
A12: 11 | B12: Maya | C12: 60 | D12: B | E12: 60 | J12: 11 | L12: 24 | N12: 23 | P12: THU | Q12: Thursday | R12: nov | S12: March | T12: A
A13: 12 | B13: Neelam | C13: 70 | D13: B | E13: 70 | J13: 12 | L13: 26 | N13: 25 | P13: FRI | Q13: Friday | R13: dec | S13: April | T13: B
A14: 13 | B14: Ravi | C14: 30 | D14: B | E14: 30 | J14: 13 | L14: 28 | N14: 27 | P14: SAT | Q14: Saturday | R14: jan | S14: May | T14: C
A15: 14 | B15: sona | C15: 60 | D15: C | E15: 60 | J15: 14 | L15: 30 | N15: 29 | P15: SUN | Q15: Sunday | R15: feb | S15: June | T15: D
... A20: 19 | B20: Ramesh | C20: 45 | D20: B | E20: 45 | J20: 19 | L20: 40 | N20: 39 | P20: FRI | Q20: Friday | R20: jul | S20: November | T20: D
A23: Num | C23: Num
A24: 1 | C24: 1
A25: 1 | C25: 1
A26: 1 | C26: 1
A27: 1 | C27: 1
A28: 1 | C28: 1
A29: 1 | C29: 1
A30: 1 | C30: 1
A31: 1 | C31: 1
A32: 1 | C32: 1
A33: 1 | C33: 1
A34: 1 | C34: 1
A35: 1 | C35: 1
... A42: 1 | C42: 1

Sheet Cal vs formulas vs func
C1: Calculations vs Formulas vs Functions | K1: Syntax Order or structure
B4: Data | D4: Calculations | E4: Formulas | F4: Function
B5: 1
B6: 2
B7: 5
B8: 100
B9: 6 | L9: 1 | M9: 2 | N9: 3 | O9: 4 | P9: 5
B10: 5 | D10: Slow | E10: Slow | F10: Fast | K10: Syntax of a Function | L10: = | M10: Function name | N10: ( | O10: Argument / Arguments | P10: )
D11: NOT DYNAMIC | E11: DYNAMIC | F11: Dynamic

Sheet Arithmetic Functions
A1: ARITHMETIC FUNCTIONS, CELL REFERENCES & NAMED RANGES
A3: Emp Code | B3: Employee Name | C3: Address | D3: City | E3: Region | F3: Department | G3: Basic | L3: Quation
A4: 1 | B4: JP Kumar | C4: Andheri (W) | D4: Mumbai | E4: W | F4: Training | G4: 30000 | I4: SUM | K4: =_xlfn.FORMULATEXT(J4) -> #N/A | L4: Total Salary
A5: 2 | B5: Anjali Thakur | C5: Govindpuri | D5: Delhi | E5: N | F5: Accounts | G5: 10000 | I5: AVERAGE | K5: =_xlfn.FORMULATEXT(J5) -> #N/A | L5: Avg Salary
A6: 3 | B6: Priya Agarwal | C6: Sector 9 | D6: Noida | E6: N | F6: Marketing | G6: 11250 | I6: MAX | K6: =_xlfn.FORMULATEXT(J6) -> #N/A | L6: Min Salary
A7: 4 | B7: R Vasu | C7: Egmore | D7: Chennai | E7: S | F7: R&D | G7: 10000 | I7: MIN | K7: =_xlfn.FORMULATEXT(J7) -> #N/A | L7: Max Salary
A8: 5 | B8: Sanjay Gupta | C8: G K - II | D8: Delhi | E8: N | F8: Training | G8: 16250 | I8: COUNT | K8: =_xlfn.FORMULATEXT(J8) -> #N/A | L8: Count the Number of EMP
A9: 6 | B9: Jharna Biswal | C9: Link Road | D9: Cuttack | E9: E | F9: Accounts | G9: 6400 | I9: COUNTA | K9: =_xlfn.FORMULATEXT(J9) -> #N/A | L9: Count the Blank
A10: 7 | B10: Prakash Dutta | C10: Elgin Road | D10: Kolkata | E10: E | F10: Marketing | G10: 4500 | I10: COUNTBLANK | K10: =_xlfn.FORMULATEXT(J10) -> #N/A | L10: count employees whose salary = 10000
A11: 8 | B11: Manisha Guha | C11: Alipore | D11: Kolkata | E11: E | F11: R&D | G11: 6275 | I11: COUNTIF | K11: =_xlfn.FORMULATEXT(J11) -> #N/A | L11: Count of employees working in the Training Department
A12: 9 | B12: Arjun Jain | C12: MG Road | D12: Mumbai | E12: W | F12: Training | G12: 6250 | I12: COUNTIF | K12: =_xlfn.FORMULATEXT(J12) -> #N/A | L12: Sum of basic salary for employees working in the Training Department
A13: 10 | B13: Arjun Kapoor | C13: Kormangala | D13: Bangalore | E13: S | F13: Accounts | G13: 8750 | I13: SUMIF | K13: =_xlfn.FORMULATEXT(J13) -> #N/A | L13: AVG of basic salary for employees working in the Training Department
A14: 11 | B14: Abrar | C14: Jayanagar | D14: Bangalore | E14: S | F14: Marketing | G14: 11250 | I14: AVERAGEIF | K14: =_xlfn.FORMULATEXT(J14) -> #N/A
A15: 12 | B15: Shahid Khan | C15: M.G Road | D15: Mangalore | E15: S | F15: R&D | G15: 10000 | L15: Total basic salary of employees working in the Training Department and residing in the W region
A16: 13 | B16: Anupam Mishra | C16: Govindpuri | D16: Mysore | E16: S | F16: Training | G16: 16250 | I16: SUMIFS | K16: =_xlfn.FORMULATEXT(J16) -> #N/A | L16: AVG basic salary of employees working in the Training Department and residing in the W region
A17: 14 | B17: Ashwini | C17: Sector 9 | D17: Mangalore | E17: S | F17: Accounts | G17: 6400 | I17: AVERAGEIFS | K17: =_xlfn.FORMULATEXT(J17) -> #N/A | L17: MAX basic salary of employees working in the Training Department and residing in the W region
A18: 15 | B18: Prateek Babbar | C18: North Road | D18: Delhi | E18: N | F18: Marketing | G18: 2000 | I18: COUNTIFS | K18: =_xlfn.FORMULATEXT(J18) -> #N/A | L18: Min basic salary of employees working in the Training Department and residing in the W region
A19: 16 | B19: Sukanya Reddy | C19: Alipore | D19: Mangalore | E19: S | F19: R&D | G19: 6275 | I19: MAXIFS | K19: =_xlfn.FORMULATEXT(J19) -> #N/A | L19: Count of employees working in the Training Department and residing in the W region
A20: 17 | B20: Satish Puri | C20: Bandra | D20: Mumbai | E20: W | F20: Operation | G20: 6250 | I20: MINIFS | K20: =_xlfn.FORMULATEXT(J20) -> #N/A
A21: 18 | B21: Anjum Chopra | C21: Worli | D21: Mumbai | E21: W | F21: R&D | G21: 8750 | I21: RANK | K21: =_xlfn.FORMULATEXT(J21) -> #N/A | L21: Rank in ASSANDING Order
A22: 19 | B22: Akram Khan | C22: S P B Road | D22: Pune | E22: W | F22: Operation | G22: 11250 | I22: RANK | K22: =_xlfn.FORMULATEXT(J22) -> #N/A | L22: Rank in Desending Order
A23: 20 | B23: Manish Grover | C23: L L R Road | D23: Noida | E23: N | F23: Training | G23: 20000 | I23: LARGE | K23: =_xlfn.FORMULATEXT(J23) -> #N/A | L23: 2nd Largest Salary Amt
I24: SMALL | K24: =_xlfn.FORMULATEXT(J24) -> #N/A | L24: 1st Smallest Salary Amt
I31: Measures of central Tendency
B32: 1
B33: 2 | I33: MEAN | J33: Avg
B34: 2 | I34: MODE
B35: 4 | I35: Median
B36: 5
B37: 5
B40: 1
B41: 2
B42: 3
B43: 4
B44: 5
B45: 6

Sheet Name Range
A1: NAMED RANGES
B3: Product name | C3: Quantity | D3: Rate | E3: Amount
B4: Textbook | C4: 16 | D4: 50 | E4: =C4*D4 -> 800
B5: Pencil | C5: 20 | D5: 30 | E5: =C5*D5 -> 600
B6: Book | C6: 25 | D6: 40 | E6: =C6*D6 -> 1000
B7: phone | C7: 18 | D7: 11 | E7: =C7*D7 -> 198
B8: 7-up | C8: 30 | D8: 12.33 | E8: =C8*D8 -> 369.9
B9: sugar | C9: 12 | D9: 15 | E9: =C9*D9 -> 180
B10: ring | C10: 4 | D10: 18 | E10: =C10*D10 -> 72

Sheet Cell References
A1: CELL REFERENCES
C3: Relative Demo | I3: Absolute Referencing demo | P3: Tax Rat | T3: Mixd Referencing
P4: 0.1
B6: Product name | C6: Quantity | D6: Rate | E6: Amount | I6: EMP NAME | J6: Salary | K6: Tax | T6: 1 | U6: 2 | V6: 3 | W6: 4 | X6: 5 | Y6: 6 | Z6: 7 | AA6: 8 | AB6: 9 | AC6: 10
B7: Pent | C7: 16 | D7: 50 | I7: JP Kumar | J7: 30000 | T7: 2
B8: pencil | C8: 20 | D8: 30 | I8: Anjali Thakur | J8: 8750 | T8: 3
B9: Book | C9: 25 | D9: 40 | I9: Priya Agarwal | J9: 11250 | T9: 4
B10: phone | C10: 18 | D10: 11 | I10: R Vasu | J10: 10000 | T10: 5
B11: 7-up | C11: 30 | D11: 12.33 | I11: Sanjay Gupta | J11: 16250 | T11: 6
B12: sugar | C12: 12 | D12: 15 | I12: Jharna Biswal | J12: 6400 | T12: 7
B13: ring | C13: 4 | D13: 18 | I13: Prakash Dutta | J13: 4500 | T13: 8
I14: Manisha Guha | J14: 6275 | T14: 9
T15: 10
U21: =_xlfn.FORMULATEXT(U7) -> #N/A

Sheet Date functions
A1: DATE, TEXT & INFORMATION FUNCTIONS
R3: project stat day is given & holidays are given need to know date , when the project get completed | Z3: following data are given from the company and they want to know when the emp contact will get end
B5: Date | D5: ctrl + ; | E5: NOT DYNAMIC | K5: Date | L5: day | M5: month | N5: Year | O5: Date | R5: Start Day | S5: 44927 | W5: holiday list | AC5: EDATE | AF5: EOMONTH
B6: Time | D6: CTRL+SHIFT+; | E6: NOT DYNAMIC | K6: 45632 | R6: No.of days | S6: 250 | W6: 44931 | Z6: Emp name | AA6: Date DOJ | AB6: NO.OF month(Contract) | AC6: last working days | AF6: full & final date in same month | AG6: one month
B7: Today | D7: =_xlfn.FORMULATEXT(C7) -> #N/A | E7: DYNAMIC / WHENEVERE YOU OPEN THE DATA GET CHANGE OUTOMATICALLY | L7: =_xlfn.FORMULATEXT(L6) -> #N/A | M7: =_xlfn.FORMULATEXT(M6) -> #N/A | N7: =_xlfn.FORMULATEXT(N6) -> #N/A | O7: =_xlfn.FORMULATEXT(O6) -> #N/A | W7: 45051 | Z7: JP Kumar | AA7: 45268 | AB7: 60
B8: Now | D8: =_xlfn.FORMULATEXT(C8) -> #N/A | W8: 45267 | Z8: Anjali Thakur | AA8: 45275 | AB8: 120
B9: TIME | D9: =_xlfn.FORMULATEXT(C9) -> #N/A | E9: IF WE WANT ONLY TIME NOT DATE | W9: 45128 | Z9: Priya Agarwal | AA9: 45267 | AB9: 40
Q10: Workday | T10: =_xlfn.FORMULATEXT(S10) -> #N/A | Z10: R Vasu | AA10: 41671 | AB10: 30
K11: Time | L11: hour | M11: Minute | N11: Second | O11: time | Q11: Workday.intl | T11: =_xlfn.FORMULATEXT(S11) -> #N/A | Z11: Sanjay Gupta | AA11: 45306 | AB11: 60
K12: 0.35023148 | Z12: Jharna Biswal | AA12: 45278 | AB12: 40
L13: =_xlfn.FORMULATEXT(L12) -> #N/A | M13: =_xlfn.FORMULATEXT(M12) -> #N/A | N13: =_xlfn.FORMULATEXT(N12) -> #N/A | O13: =_xlfn.FORMULATEXT(O12) -> #N/A | Z13: Prakash Dutta | AA13: 45518 | AB13: 48
Z14: Manisha Guha | AA14: 41688 | AB14: 24
Z15: Arjun Jain | AA15: 45487 | AB15: 50
Z16: Arjun Kapoor | AA16: 41671 | AB16: 70
J17: Text
AG19: =_xlfn.FORMULATEXT(AG7) -> #N/A
K29: Start date | L29: 17394
K30: end date | L30: =TODAY() -> 46269
K32: how to find days
K33: DAYS
K34: DATEDIF GIVE YOU DAY,MONTH,YEAR
K35: Yearfrac
J44: Weekday | K44: 45658 | M44: =_xlfn.FORMULATEXT(L44) -> #N/A
J45: Weeknum | M45: =_xlfn.FORMULATEXT(L45) -> #N/A
I47: Networkday | J47: start date | K47: 44927
I48: Networkdays.intl | J48: end date | K48: 45291
I51: holiday list | L51: =_xlfn.FORMULATEXT(K51) -> #N/A
I52: 44931 | L52: =_xlfn.FORMULATEXT(K52) -> #N/A
I53: 45051
I54: 45267
I55: 45128

Sheet Text functions
B1: DATE, TEXT & INFORMATION FUNCTIONS
B4: Employee name | C4: UPPER | D4: LOWER | E4: PROPER | F4: LEN | I4: Employee name | J4: Trim | M4: Employee name | N4: Left | O4: Right | P4: Mid | S4: Employee name | T4: Surname | U4: Concatenate | V4: & (oprater) | Y4: Employee name | Z4: Employee name | AA4: Exact (case sensitive) | AB4: oprator (=) | AC4: Find (case sensitive) | AD4: Search (not case sensitive) | AE4: substitute (case sensitive) | AH4: Data | AI4: Replace
B5: JP KUMAr | I5: JP KUMAR | M5: JP KUMAr | S5: JP | T5: Kumar | Y5: JP KUMAR | Z5: JP Kumar | AH5: Sales data
B6: KAVITa Lalwani | I6: Kavita Lalwani | M6: KAVITa Lalwani | S6: Kavita | T6: Lalwani | Y6: Kavita Lalwani | Z6: Kavita Lalwani | AH6: Manglore
B7: priya AgrwaL | I7: Priya AgrwaL | M7: priya AgrwaL | S7: Priya | T7: Agrwal | Y7: Priya AgrwaL | Z7: Priya Agrwal | AH7: cost sheet
B8: R Vasu | I8: R Vasu | M8: R Vasu | S8: R | T8: Vasu | Y8: R Vasu | Z8: R Vasu
B9: SanjaY guPTA | I9: Sanjay Gupta | M9: SanjaY guPTA | S9: Sanjay | T9: Gupta | Y9: Sanjay Gupta | Z9: Sanjay Gupta
B10: Jhrna Bnsal | I10: Jhrna Bansal | M10: Jhrna Bnsal | S10: Jhrna | T10: Bansal | Y10: Jhrna Bansal | Z10: Jhara Bansal
B11: ARUN jInwari | I11: Arun KapuR | M11: ARUN jInwari | S11: Arun | T11: Kapoor | Y11: Arun KapuR | Z11: Arun Kapoor | AH11: =_xlfn.FORMULATEXT(AI5) -> #N/A
B12: arjun KpooR | I12: Arjun Kapoor | M12: arjun KpooR | S12: Arjun | T12: Kapoor | Y12: Arjun Kapoor | Z12: arjun Kapoor | AH12: =_xlfn.FORMULATEXT(AI6) -> #N/A
B13: JAYYAA | I13: Radhika Srivastava | M13: JAYYAA | S13: Radhika | T13: Srivastava | Y13: Radhika Srivastava | Z13: Radhika Srivastava | AH13: =_xlfn.FORMULATEXT(AI7) -> #N/A
B14: RADHIka srivasTAv | M14: RADHIka srivasTAv
AA15: =_xlfn.FORMULATEXT(AA5) -> #N/A | AB15: =_xlfn.FORMULATEXT(AB5) -> #N/A | AC15: =_xlfn.FORMULATEXT(AC5) -> #N/A | AD15: =_xlfn.FORMULATEXT(AD5) -> #N/A | AE15: =_xlfn.FORMULATEXT(AE5) -> #N/A
C16: =_xlfn.FORMULATEXT(C5) -> #N/A | D16: =_xlfn.FORMULATEXT(D5) -> #N/A | E16: =_xlfn.FORMULATEXT(E5) -> #N/A | F16: =_xlfn.FORMULATEXT(F5) -> #N/A | J16: =_xlfn.FORMULATEXT(J5) -> #N/A | N16: =_xlfn.FORMULATEXT(N5) -> #N/A | O16: =_xlfn.FORMULATEXT(O5) -> #N/A | P16: =_xlfn.FORMULATEXT(P5) -> #N/A | U16: =_xlfn.FORMULATEXT(U5) -> #N/A | V16: =_xlfn.FORMULATEXT(V5) -> #N/A

Sheet Flash fill & text to column
A1: FLASH FILL, TABLE CREATION & DATA VALIDATION
B3: Fill series
B6: Liner | F6: Growth do multip | I6: Date | R6: Autofill
L7: DAY | N7: MONTH | O7: Year | P7: weekday
I8: 44927
I9: 44927
I10: 44927
I11: 44927
I12: 44927
I13: 44927
I14: 44927
I15: 44927
I16: 44927
I17: 44927
I18: 44927
I19: 44927
... I22: 44927
B26: Flashfill
B30: First Name | C30: Last Name | D30: Example -1 | E30: first name Exampl | F30: Example -2 | G30: Example -3 | H30: Example -4 | I30: Example -5
B31: JP | C31: Kumar
B32: Anjali | C32: Thakur
B33: Priya | C33: Agarwal
B34: R | C34: Vasu
B35: Sanjay | C35: Gupta
B36: Jharna | C36: Biswal
B37: Prakash | C37: Dutta
B38: Manisha | C38: Guha
B39: Arjun | C39: Jain
B40: Arjun | C40: Kapoor
B44: emp code | C44: emp name | D44: Address | E44: City | F44: Region | G44: dept | H44: Unique id | K44: CTRL + E
B45: 1 | C45: JP Kumar | D45: andheri | E45: mumbai | F45: w | G45: Trining
B46: 2 | C46: Anjali Thakur | D46: linkroad | E46: pune | F46: w | G46: acounting
B47: 3 | C47: Priya Agarwal | D47: koper | E47: delhi | F47: n | G47: marketing
B48: 4 | C48: R Vasu | D48: telana | E48: noida | F48: n | G48: Trining | K48: Unique id
B49: 5 | C49: Sanjay Gupta | D49: kondapur | E49: chennai | F49: s | G49: acounting
B50: 6 | C50: Jharna Biswal | D50: linkroad | E50: kolkatta | F50: e | G50: marketing
B51: 7 | C51: Prakash Dutta | D51: kore road | E51: mumbai | F51: w | G51: marketing
B52: 8 | C52: Manisha Guha | D52: boriwal | E52: Hyderabad | F52: s | G52: marketing
B53: 9 | C53: Arjun Jain | D53: uppal | E53: Hyderabad | F53: s | G53: acounting
B54: 10 | C54: Arjun Kapoor | D54: whitefild | E54: mumbai | F54: w | G54: acounting
...

Sheet Information function
A1: INFORMATION FUNCTIONS
B4: Functions | C4: Data
B5: Istext | C5: Excelr | E5: =_xlfn.FORMULATEXT(D5) -> #N/A
B6: Isnumber | C6: 2012 | E6: =_xlfn.FORMULATEXT(D6) -> #N/A
B7: Isnontext | C7: 1989 | E7: =_xlfn.FORMULATEXT(D7) -> #N/A
B8: Iseven | C8: 12 | E8: =_xlfn.FORMULATEXT(D8) -> #N/A
B9: Isodd | C9: 5 | E9: =_xlfn.FORMULATEXT(D9) -> #N/A
B10: isformula | C10: =TODAY() -> 46269 | E10: =_xlfn.FORMULATEXT(D10) -> #N/A
B11: islogical | C11: TRUE | E11: =_xlfn.FORMULATEXT(D11) -> #N/A
B12: isblank | E12: =_xlfn.FORMULATEXT(D12) -> #N/A
B13: ISNA | C13: #N/A | E13: =_xlfn.FORMULATEXT(D13) -> #N/A
C14: EXLR123 | E14: =_xlfn.FORMULATEXT(D14) -> #N/A

Sheet Paste special & Math & trigo
B1: Paste special funcation
B4: Transpose
D6: Transpose data in Horizontal format
C8: Region
C9: North
C10: east
C11: west
C12: 455
C13: central
C14: north-east
C15: south-west
C16: north-west
C17: south-east
D19: Transpose data in vertical format
C21: Region | D21: North | E21: east | F21: west | G21: 455 | H21: central | I21: north-east | J21: south-west | K21: north-west | L21: south-east
B36: Paste link
B38: Region
B39: north
B40: kavita
B41: west
B42: Kavita
B43: Excelr
B44: west
B45: south-west
B46: north-west
B47: south-east
B51: Skip Blank
B54: Region | C54: Sales Data
B55: North | C55: 50
B56: kavita | C56: 89
B57: west
B58: north-east | C58: 60
B59: Central e | C59: 40
B60: north-east | C60: 20
B61: south-west
B62: north-west | C62: 70
B63: south-east | C63: 500
B66: Paste special opration
B69: Data | C69: Add | D69: Substract | E69: Multiply | F69: Divide | G69: Data | H69: Data | K69: Value | L69: 10 | M69: -1
B70: 60
...

Sheet Sumproduct & Indirect
A1: Sumproduct
B4: Product Name | C4: Price per unit | D4: Quantity | E4: Total Amount
B5: Pen | C5: 30 | D5: 25
B6: Milk | C6: 40 | D6: 20
B7: Bread | C7: 20 | D7: 40
B8: Colour | C8: 25 | D8: 80
B9: Book | C9: 100 | D9: 60
B10: Pen stand | C10: 300 | D10: 20
B11: story book | C11: 150 | D11: 50
B12: Water Bottle | C12: 200 | D12: 100
B13: Tea | C13: 300 | D13: 200
A18: Indirect Function
B21: Product name | C21: Quantity | D21: Rate | E21: Amount
B22: Pen | C22: 16 | D22: 50 | E22: =C22*D22 -> 800
B23: Milk | C23: 20 | D23: 30 | E23: =C23*D23 -> 600
B24: Bread | C24: 25 | D24: 40 | E24: =C24*D24 -> 1000
B25: Colour | C25: 18 | D25: 11 | E25: =C25*D25 -> 198
B26: Book | C26: 30 | D26: 12.33 | E26: =C26*D26 -> 369.9
B27: Pen stand | C27: 12 | D27: 15 | E27: =C27*D27 -> 180
B28: story book | C28: 4 | D28: 18 | E28: =C28*D28 -> 72
B29: Water Bottle | C29: 6 | D29: 20 | E29: =C29*D29 -> 120
B30: Tea | C30: 15 | D30: 40 | E30: =C30*D30 -> 600

Sheet Data Validation
A1: Data Validation
A5: Emp Code | B5: Basic Salary | C5: Dept | D5: Region | E5: Department | F5: DOJ | G5: time | H5: Gender | K5: Mobile num | L5: Mobile num with custom | N5: Data sal
B6: 0 | C6: HR | D6: N | E6: Accounts | N6: 1000
B7: 0 | C7: Accounts | G7: 0.083333333 | N7: 2000
C8: Research | N8: 3000
C9: Operations | G9: 0.0069444444 | N9: 5000
B10: 500 | F10: 46082 | N10: 6000
B11: 10000 | N11: 8000
B12: 100000 | N12: 5000
A13: 12 | B13: 100000 | G13: 0.375 | N13: 1000
N14: 3000
A15: 11 | N15: 9000
N16: 8000
N17: 7000
N18: 10000
N19: 4000
N20: 6000
N21: 2000
N22: 20000

Sheet Logical function
D1: Logical Function
S4: =_xlfn.FORMULATEXT(S6) -> =G6+H6+I6+J6+L6+P6+Q6+R6 | T4: =_xlfn.FORMULATEXT(T6) -> =S6-P6-L6
A5: Emp Code | B5: Employee Name | C5: Address | D5: City | E5: Region | F5: Department | G5: Basic | H5: DA | I5: HRA | J5: TA | K5: Basic With TA total | L5: PF | M5: BONUS | N5: INCENTIVE | O5: OVERTIME | P5: P.TAX | Q5: CCA | R5: SPECIAL ALLOWANCE | S5: GROSS SALARY | T5: NET SALARY
A6: 1 | B6: JP Kumar | C6: Andheri (W) | D6: Mumbai | E6: W | F6: Training | G6: 30000 | H6: =G6*30% -> 9000 | I6: =(G6+H6)*40% -> 15600 | J6: {=IF(F6:F25="Marketing",5000,0)} -> 0 | K6: {=IF(F6:F25="Marketing",G6:G25+5000,G6:G25)} -> 30000 | L6: =G6*12% -> 3600 | M6: =IF(AND(F6="Training",E6="W"),G6*40%,0) -> 12000 | N6: =IF(OR(F6="Accounts",F6="Operation"),5000,0) -> 0 | O6: =IF(OR(F6="Accounts",F6="operation"),0,3500) -> 3500 | P6: =IF(G6<5000,0,IF(G6<=10000,50,IF(G6<=15000,100,IF(G6<=20000,150,200)))) -> 200 | Q6: =IF(OR(D6="mumbai",D6="Delhi",D6="kolkata",D6="Chennai",D6="bangalore"),5000,0) -> 5000 | R6: =IF(OR(AND(F6="Training",E6="w"),AND(F6="Marketing",E6="N"),AND(F6="R&D",E6="S"),AND(F6="accounts",E6="E")),G6*30%,0) -> 9000 | S6: =G6+H6+I6+J6+L6+P6+Q6+R6 -> 72400 | T6: =S6-P6-L6 -> 68600
A7: 2 | B7: Anjali Thakur | C7: Govindpuri | D7: Delhi | E7: N | F7: Accounts | G7: 8750 | H7: =G7*30% -> 2625 | I7: =(G7+H7)*40% -> 4550 | J7: 0 | K7: 8750 | L7: =G7*12% -> 1050 | M7: =IF(AND(F7="Training",E7="W"),G7*40%,0) -> 0 | N7: =IF(OR(F7="Accounts",F7="Operation"),5000,0) -> 5000 | O7: =IF(OR(F7="Accounts",F7="operation"),0,3500) -> 0 | P7: =IF(G7<5000,0,IF(G7<=10000,50,IF(G7<=15000,100,IF(G7<=20000,150,200)))) -> 50 | Q7: =IF(OR(D7="mumbai",D7="Delhi",D7="kolkata",D7="Chennai",D7="bangalore"),5000,0) -> 5000 | R7: =IF(OR(AND(F7="Training",E7="w"),AND(F7="Marketing",E7="N"),AND(F7="R&D",E7="S"),AND(F7="accounts",E7="E")),G7*30%,0) -> 0 | S7: =G7+H7+I7+J7+L7+P7+Q7+R7 -> 22025 | T7: =S7-P7-L7 -> 20925 | U7: P.TAX
A8: 3 | B8: Priya Agarwal | C8: Sector 9 | D8: Noida | E8: N | F8: Marketing | G8: 11250 | H8: =G8*30% -> 3375 | I8: =(G8+H8)*40% -> 5850 | J8: 5000 | K8: 16250 | L8: =G8*12% -> 1350 | M8: =IF(AND(F8="Training",E8="W"),G8*40%,0) -> 0 | N8: =IF(OR(F8="Accounts",F8="Operation"),5000,0) -> 0 | O8: =IF(OR(F8="Accounts",F8="operation"),0,3500) -> 3500 | P8: =IF(G8<5000,0,IF(G8<=10000,50,IF(G8<=15000,100,IF(G8<=20000,150,200)))) -> 100 | Q8: =IF(OR(D8="mumbai",D8="Delhi",D8="kolkata",D8="Chennai",D8="bangalore"),5000,0) -> 0 | R8: =IF(OR(AND(F8="Training",E8="w"),AND(F8="Marketing",E8="N"),AND(F8="R&D",E8="S"),AND(F8="accounts",E8="E")),G8*30%,0) -> 3375 | S8: =G8+H8+I8+J8+L8+P8+Q8+R8 -> 30300 | T8: =S8-P8-L8 -> 28850 | U8: <5000 | V8: 0
A9: 4 | B9: R Vasu | C9: Egmore | D9: Chennai | E9: S | F9: R&D | G9: 10000 | H9: =G9*30% -> 3000 | I9: =(G9+H9)*40% -> 5200 | J9: 0 | K9: 10000 | L9: =G9*12% -> 1200 | M9: =IF(AND(F9="Training",E9="W"),G9*40%,0) -> 0 | N9: =IF(OR(F9="Accounts",F9="Operation"),5000,0) -> 0 | O9: =IF(OR(F9="Accounts",F9="operation"),0,3500) -> 3500 | P9: =IF(G9<5000,0,IF(G9<=10000,50,IF(G9<=15000,100,IF(G9<=20000,150,200)))) -> 50 | Q9: =IF(OR(D9="mumbai",D9="Delhi",D9="kolkata",D9="Chennai",D9="bangalore"),5000,0) -> 5000 | R9: =IF(OR(AND(F9="Training",E9="w"),AND(F9="Marketing",E9="N"),AND(F9="R&D",E9="S"),AND(F9="accounts",E9="E")),G9*30%,0) -> 3000 | S9: =G9+H9+I9+J9+L9+P9+Q9+R9 -> 27450 | T9: =S9-P9-L9 -> 26200 | U9: >= 5000 & <=10000 | V9: 50
A10: 5 | B10: Sanjay Gupta | C10: G K - II | D10: Delhi | E10: N | F10: Training | G10: 16250 | H10: =G10*30% -> 4875 | I10: =(G10+H10)*40% -> 8450 | J10: 0 | K10: 16250 | L10: =G10*12% -> 1950 | M10: =IF(AND(F10="Training",E10="W"),G10*40%,0) -> 0 | N10: =IF(OR(F10="Accounts",F10="Operation"),5000,0) -> 0 | O10: =IF(OR(F10="Accounts",F10="operation"),0,3500) -> 3500 | P10: =IF(G10<5000,0,IF(G10<=10000,50,IF(G10<=15000,100,IF(G10<=20000,150,200)))) -> 150 | Q10: =IF(OR(D10="mumbai",D10="Delhi",D10="kolkata",D10="Chennai",D10="bangalore"),5000,0) -> 5000 | R10: =IF(OR(AND(F10="Training",E10="w"),AND(F10="Marketing",E10="N"),AND(F10="R&D",E10="S"),AND(F10="accounts",E10="E")),G10*30%,0) -> 0 | S10: =G10+H10+I10+J10+L10+P10+Q10+R10 -> 36675 | T10: =S10-P10-L10 -> 34575 | U10: >10000 & <=15000 | V10: 100
A11: 6 | B11: Jharna Biswal | C11: Link Road | D11: Cuttack | E11: E | F11: Accounts | G11: 6400 | H11: =G11*30% -> 1920 | I11: =(G11+H11)*40% -> 3328 | J11: 0 | K11: 6400 | L11: =G11*12% -> 768 | M11: =IF(AND(F11="Training",E11="W"),G11*40%,0) -> 0 | N11: =IF(OR(F11="Accounts",F11="Operation"),5000,0) -> 5000 | O11: =IF(OR(F11="Accounts",F11="operation"),0,3500) -> 0 | P11: =IF(G11<5000,0,IF(G11<=10000,50,IF(G11<=15000,100,IF(G11<=20000,150,200)))) -> 50 | Q11: =IF(OR(D11="mumbai",D11="Delhi",D11="kolkata",D11="Chennai",D11="bangalore"),5000,0) -> 0 | R11: =IF(OR(AND(F11="Training",E11="w"),AND(F11="Marketing",E11="N"),AND(F11="R&D",E11="S"),AND(F11="accounts",E11="E")),G11*30%,0) -> 1920 | S11: =G11+H11+I11+J11+L11+P11+Q11+R11 -> 14386 | T11: =S11-P11-L11 -> 13568 | U11: >15000 & <=20000 | V11: 150
A12: 7 | B12: Prakash Dutta | C12: Elgin Road | D12: Kolkata | E12: E | F12: Marketing | G12: 4500 | H12: =G12*30% -> 1350 | I12: =(G12+H12)*40% -> 2340 | J12: 5000 | K12: 9500 | L12: =G12*12% -> 540 | M12: =IF(AND(F12="Training",E12="W"),G12*40%,0) -> 0 | N12: =IF(OR(F12="Accounts",F12="Operation"),5000,0) -> 0 | O12: =IF(OR(F12="Accounts",F12="operation"),0,3500) -> 3500 | P12: =IF(G12<5000,0,IF(G12<=10000,50,IF(G12<=15000,100,IF(G12<=20000,150,200)))) -> 0 | Q12: =IF(OR(D12="mumbai",D12="Delhi",D12="kolkata",D12="Chennai",D12="bangalore"),5000,0) -> 5000 | R12: =IF(OR(AND(F12="Training",E12="w"),AND(F12="Marketing",E12="N"),AND(F12="R&D",E12="S"),AND(F12="accounts",E12="E")),G12*30%,0) -> 0 | S12: =G12+H12+I12+J12+L12+P12+Q12+R12 -> 18730 | T12: =S12-P12-L12 -> 18190 | U12: >20000 | V12: 200
A13: 8 | B13: Manisha Guha | C13: Alipore | D13: Kolkata | E13: E | F13: R&D | G13: 6275 | H13: =G13*30% -> 1882.5 | I13: =(G13+H13)*40% -> 3263 | J13: 0 | K13: 6275 | L13: =G13*12% -> 753 | M13: =IF(AND(F13="Training",E13="W"),G13*40%,0) -> 0 | N13: =IF(OR(F13="Accounts",F13="Operation"),5000,0) -> 0 | O13: =IF(OR(F13="Accounts",F13="operation"),0,3500) -> 3500 | P13: =IF(G13<5000,0,IF(G13<=10000,50,IF(G13<=15000,100,IF(G13<=20000,150,200)))) -> 50 | Q13: =IF(OR(D13="mumbai",D13="Delhi",D13="kolkata",D13="Chennai",D13="bangalore"),5000,0) -> 5000 | R13: =IF(OR(AND(F13="Training",E13="w"),AND(F13="Marketing",E13="N"),AND(F13="R&D",E13="S"),AND(F13="accounts",E13="E")),G13*30%,0) -> 0 | S13: =G13+H13+I13+J13+L13+P13+Q13+R13 -> 17223.5 | T13: =S13-P13-L13 -> 16420.5
A14: 9 | B14: Arjun Jain | C14: MG Road | D14: Mumbai | E14: W | F14: Training | G14: 6250 | H14: =G14*30% -> 1875 | I14: =(G14+H14)*40% -> 3250 | J14: 0 | K14: 6250 | L14: =G14*12% -> 750 | M14: =IF(AND(F14="Training",E14="W"),G14*40%,0) -> 2500 | N14: =IF(OR(F14="Accounts",F14="Operation"),5000,0) -> 0 | O14: =IF(OR(F14="Accounts",F14="operation"),0,3500) -> 3500 | P14: =IF(G14<5000,0,IF(G14<=10000,50,IF(G14<=15000,100,IF(G14<=20000,150,200)))) -> 50 | Q14: =IF(OR(D14="mumbai",D14="Delhi",D14="kolkata",D14="Chennai",D14="bangalore"),5000,0) -> 5000 | R14: =IF(OR(AND(F14="Training",E14="w"),AND(F14="Marketing",E14="N"),AND(F14="R&D",E14="S"),AND(F14="accounts",E14="E")),G14*30%,0) -> 1875 | S14: =G14+H14+I14+J14+L14+P14+Q14+R14 -> 19050 | T14: =S14-P14-L14 -> 18250
A15: 10 | B15: Arjun Kapoor | C15: Kormangala | D15: Bangalore | E15: S | F15: Accounts | G15: 8750 | H15: =G15*30% -> 2625 | I15: =(G15+H15)*40% -> 4550 | J15: 0 | K15: 8750 | L15: =G15*12% -> 1050 | M15: =IF(AND(F15="Training",E15="W"),G15*40%,0) -> 0 | N15: =IF(OR(F15="Accounts",F15="Operation"),5000,0) -> 5000 | O15: =IF(OR(F15="Accounts",F15="operation"),0,3500) -> 0 | P15: =IF(G15<5000,0,IF(G15<=10000,50,IF(G15<=15000,100,IF(G15<=20000,150,200)))) -> 50 | Q15: =IF(OR(D15="mumbai",D15="Delhi",D15="kolkata",D15="Chennai",D15="bangalore"),5000,0) -> 5000 | R15: =IF(OR(AND(F15="Training",E15="w"),AND(F15="Marketing",E15="N"),AND(F15="R&D",E15="S"),AND(F15="accounts",E15="E")),G15*30%,0) -> 0 | S15: =G15+H15+I15+J15+L15+P15+Q15+R15 -> 22025 | T15: =S15-P15-L15 -> 20925
A16: 11 | B16: Abrar | C16: Jayanagar | D16: Bangalore | E16: S | F16: Marketing | G16: 11250 | H16: =G16*30% -> 3375 | I16: =(G16+H16)*40% -> 5850 | J16: 5000 | K16: 16250 | L16: =G16*12% -> 1350 | M16: =IF(AND(F16="Training",E16="W"),G16*40%,0) -> 0 | N16: =IF(OR(F16="Accounts",F16="Operation"),5000,0) -> 0 | O16: =IF(OR(F16="Accounts",F16="operation"),0,3500) -> 3500 | P16: =IF(G16<5000,0,IF(G16<=10000,50,IF(G16<=15000,100,IF(G16<=20000,150,200)))) -> 100 | Q16: =IF(OR(D16="mumbai",D16="Delhi",D16="kolkata",D16="Chennai",D16="bangalore"),5000,0) -> 5000 | R16: =IF(OR(AND(F16="Training",E16="w"),AND(F16="Marketing",E16="N"),AND(F16="R&D",E16="S"),AND(F16="accounts",E16="E")),G16*30%,0) -> 0 | S16: =G16+H16+I16+J16+L16+P16+Q16+R16 -> 31925 | T16: =S16-P16-L16 -> 30475 | U16: Training | V16: W | W16: 30%*BASIC
A17: 12 | B17: Shahid Khan | C17: M.G Road | D17: Mangalore | E17: S | F17: R&D | G17: 10000 | H17: =G17*30% -> 3000 | I17: =(G17+H17)*40% -> 5200 | J17: 0 | K17: 10000 | L17: =G17*12% -> 1200 | M17: =IF(AND(F17="Training",E17="W"),G17*40%,0) -> 0 | N17: =IF(OR(F17="Accounts",F17="Operation"),5000,0) -> 0 | O17: =IF(OR(F17="Accounts",F17="operation"),0,3500) -> 3500 | P17: =IF(G17<5000,0,IF(G17<=10000,50,IF(G17<=15000,100,IF(G17<=20000,150,200)))) -> 50 | Q17: =IF(OR(D17="mumbai",D17="Delhi",D17="kolkata",D17="Chennai",D17="bangalore"),5000,0) -> 0 | R17: =IF(OR(AND(F17="Training",E17="w"),AND(F17="Marketing",E17="N"),AND(F17="R&D",E17="S"),AND(F17="accounts",E17="E")),G17*30%,0) -> 3000 | S17: =G17+H17+I17+J17+L17+P17+Q17+R17 -> 22450 | T17: =S17-P17-L17 -> 21200 | U17: Marketing | V17: N
A18: 13 | B18: Anupam Mishra | C18: Govindpuri | D18: Mysore | E18: S | F18: Training | G18: 16250 | H18: =G18*30% -> 4875 | I18: =(G18+H18)*40% -> 8450 | J18: 0 | K18: 16250 | L18: =G18*12% -> 1950 | M18: =IF(AND(F18="Training",E18="W"),G18*40%,0) -> 0 | N18: =IF(OR(F18="Accounts",F18="Operation"),5000,0) -> 0 | O18: =IF(OR(F18="Accounts",F18="operation"),0,3500) -> 3500 | P18: =IF(G18<5000,0,IF(G18<=10000,50,IF(G18<=15000,100,IF(G18<=20000,150,200)))) -> 150 | Q18: =IF(OR(D18="mumbai",D18="Delhi",D18="kolkata",D18="Chennai",D18="bangalore"),5000,0) -> 0 | R18: =IF(OR(AND(F18="Training",E18="w"),AND(F18="Marketing",E18="N"),AND(F18="R&D",E18="S"),AND(F18="accounts",E18="E")),G18*30%,0) -> 0 | S18: =G18+H18+I18+J18+L18+P18+Q18+R18 -> 31675 | T18: =S18-P18-L18 -> 29575 | U18: R&D | V18: S
A19: 14 | B19: Ashwini | C19: Sector 9 | D19: Mangalore | E19: S | F19: Accounts | G19: 6400 | H19: =G19*30% -> 1920 | I19: =(G19+H19)*40% -> 3328 | J19: 0 | K19: 6400 | L19: =G19*12% -> 768 | M19: =IF(AND(F19="Training",E19="W"),G19*40%,0) -> 0 | N19: =IF(OR(F19="Accounts",F19="Operation"),5000,0) -> 5000 | O19: =IF(OR(F19="Accounts",F19="operation"),0,3500) -> 0 | P19: =IF(G19<5000,0,IF(G19<=10000,50,IF(G19<=15000,100,IF(G19<=20000,150,200)))) -> 50 | Q19: =IF(OR(D19="mumbai",D19="Delhi",D19="kolkata",D19="Chennai",D19="bangalore"),5000,0) -> 0 | R19: =IF(OR(AND(F19="Training",E19="w"),AND(F19="Marketing",E19="N"),AND(F19="R&D",E19="S"),AND(F19="accounts",E19="E")),G19*30%,0) -> 0 | S19: =G19+H19+I19+J19+L19+P19+Q19+R19 -> 12466 | T19: =S19-P19-L19 -> 11648 | U19: Accounts | V19: E
A20: 15 | B20: Prateek Babbar | C20: North Road | D20: Delhi | E20: N | F20: Marketing | G20: 4500 | H20: =G20*30% -> 1350 | I20: =(G20+H20)*40% -> 2340 | J20: 5000 | K20: 9500 | L20: =G20*12% -> 540 | M20: =IF(AND(F20="Training",E20="W"),G20*40%,0) -> 0 | N20: =IF(OR(F20="Accounts",F20="Operation"),5000,0) -> 0 | O20: =IF(OR(F20="Accounts",F20="operation"),0,3500) -> 3500 | P20: =IF(G20<5000,0,IF(G20<=10000,50,IF(G20<=15000,100,IF(G20<=20000,150,200)))) -> 0 | Q20: =IF(OR(D20="mumbai",D20="Delhi",D20="kolkata",D20="Chennai",D20="bangalore"),5000,0) -> 5000 | R20: =IF(OR(AND(F20="Training",E20="w"),AND(F20="Marketing",E20="N"),AND(F20="R&D",E20="S"),AND(F20="accounts",E20="E")),G20*30%,0) -> 1350 | S20: =G20+H20+I20+J20+L20+P20+Q20+R20 -> 20080 | T20: =S20-P20-L20 -> 19540
A21: 16 | B21: Sukanya Reddy | C21: Alipore | D21: Mangalore | E21: S | F21: R&D | G21: 6275 | H21: =G21*30% -> 1882.5 | I21: =(G21+H21)*40% -> 3263 | J21: 0 | K21: 6275 | L21: =G21*12% -> 753 | M21: =IF(AND(F21="Training",E21="W"),G21*40%,0) -> 0 | N21: =IF(OR(F21="Accounts",F21="Operation"),5000,0) -> 0 | O21: =IF(OR(F21="Accounts",F21="operation"),0,3500) -> 3500 | P21: =IF(G21<5000,0,IF(G21<=10000,50,IF(G21<=15000,100,IF(G21<=20000,150,200)))) -> 50 | Q21: =IF(OR(D21="mumbai",D21="Delhi",D21="kolkata",D21="Chennai",D21="bangalore"),5000,0) -> 0 | R21: =IF(OR(AND(F21="Training",E21="w"),AND(F21="Marketing",E21="N"),AND(F21="R&D",E21="S"),AND(F21="accounts",E21="E")),G21*30%,0) -> 1882.5 | S21: =G21+H21+I21+J21+L21+P21+Q21+R21 -> 14106 | T21: =S21-P21-L21 -> 13303
A22: 17 | B22: Satish Puri | C22: Bandra | D22: Mumbai | E22: W | F22: Operation | G22: 6250 | H22: =G22*30% -> 1875 | I22: =(G22+H22)*40% -> 3250 | J22: 0 | K22: 6250 | L22: =G22*12% -> 750 | M22: =IF(AND(F22="Training",E22="W"),G22*40%,0) -> 0 | N22: =IF(OR(F22="Accounts",F22="Operation"),5000,0) -> 5000 | O22: =IF(OR(F22="Accounts",F22="operation"),0,3500) -> 0 | P22: =IF(G22<5000,0,IF(G22<=10000,50,IF(G22<=15000,100,IF(G22<=20000,150,200)))) -> 50 | Q22: =IF(OR(D22="mumbai",D22="Delhi",D22="kolkata",D22="Chennai",D22="bangalore"),5000,0) -> 5000 | R22: =IF(OR(AND(F22="Training",E22="w"),AND(F22="Marketing",E22="N"),AND(F22="R&D",E22="S"),AND(F22="accounts",E22="E")),G22*30%,0) -> 0 | S22: =G22+H22+I22+J22+L22+P22+Q22+R22 -> 17175 | T22: =S22-P22-L22 -> 16375
A23: 18 | B23: Anjum Chopra | C23: Worli | D23: Mumbai | E23: W | F23: R&D | G23: 8750 | H23: =G23*30% -> 2625 | I23: =(G23+H23)*40% -> 4550 | J23: 0 | K23: 8750 | L23: =G23*12% -> 1050 | M23: =IF(AND(F23="Training",E23="W"),G23*40%,0) -> 0 | N23: =IF(OR(F23="Accounts",F23="Operation"),5000,0) -> 0 | O23: =IF(OR(F23="Accounts",F23="operation"),0,3500) -> 3500 | P23: =IF(G23<5000,0,IF(G23<=10000,50,IF(G23<=15000,100,IF(G23<=20000,150,200)))) -> 50 | Q23: =IF(OR(D23="mumbai",D23="Delhi",D23="kolkata",D23="Chennai",D23="bangalore"),5000,0) -> 5000 | R23: =IF(OR(AND(F23="Training",E23="w"),AND(F23="Marketing",E23="N"),AND(F23="R&D",E23="S"),AND(F23="accounts",E23="E")),G23*30%,0) -> 0 | S23: =G23+H23+I23+J23+L23+P23+Q23+R23 -> 22025 | T23: =S23-P23-L23 -> 20925
A24: 19 | B24: Akram Khan | C24: S P B Road | D24: Pune | E24: W | F24: Operation | G24: 11250 | H24: =G24*30% -> 3375 | I24: =(G24+H24)*40% -> 5850 | J24: 0 | K24: 11250 | L24: =G24*12% -> 1350 | M24: =IF(AND(F24="Training",E24="W"),G24*40%,0) -> 0 | N24: =IF(OR(F24="Accounts",F24="Operation"),5000,0) -> 5000 | O24: =IF(OR(F24="Accounts",F24="operation"),0,3500) -> 0 | P24: =IF(G24<5000,0,IF(G24<=10000,50,IF(G24<=15000,100,IF(G24<=20000,150,200)))) -> 100 | Q24: =IF(OR(D24="mumbai",D24="Delhi",D24="kolkata",D24="Chennai",D24="bangalore"),5000,0) -> 0 | R24: =IF(OR(AND(F24="Training",E24="w"),AND(F24="Marketing",E24="N"),AND(F24="R&D",E24="S"),AND(F24="accounts",E24="E")),G24*30%,0) -> 0 | S24: =G24+H24+I24+J24+L24+P24+Q24+R24 -> 21925 | T24: =S24-P24-L24 -> 20475
A25: 20 | B25: Manish Grover | C25: L L R Road | D25: Noida | E25: N | F25: Training | G25: 20000 | H25: =G25*30% -> 6000 | I25: =(G25+H25)*40% -> 10400 | J25: 0 | K25: 20000 | L25: =G25*12% -> 2400 | M25: =IF(AND(F25="Training",E25="W"),G25*40%,0) -> 0 | N25: =IF(OR(F25="Accounts",F25="Operation"),5000,0) -> 0 | O25: =IF(OR(F25="Accounts",F25="operation"),0,3500) -> 3500 | P25: =IF(G25<5000,0,IF(G25<=10000,50,IF(G25<=15000,100,IF(G25<=20000,150,200)))) -> 150 | Q25: =IF(OR(D25="mumbai",D25="Delhi",D25="kolkata",D25="Chennai",D25="bangalore"),5000,0) -> 0 | R25: =IF(OR(AND(F25="Training",E25="w"),AND(F25="Marketing",E25="N"),AND(F25="R&D",E25="S"),AND(F25="accounts",E25="E")),G25*30%,0) -> 0 | S25: =G25+H25+I25+J25+L25+P25+Q25+R25 -> 38950 | T25: =S25-P25-L25 -> 36400
O29: =IF(G6<5000,0,IF(G6<=10000,50,IF(G6<=15000,100,IF(G6<=20000,150,200))))
A33: IFERROR
O34: {=_xlfn.IFS(G6<=5000,0,G6<=10000,50,G6<=15000,100,G6<=20000,150,TRUE,200)} -> 200
B35: Salary | C35: Grade | E35: Salary | F35: Grade
B36: <25000 | C36: D | E36: 50000 | O36: =_xlfn.FORMULATEXT(O34) -> =IFS(G6<=5000,0,G6<=10000,50,G6<=15000,100,G6<=20000,150,TRUE,200)
B37: 25001 TO 50000 | C37: C | E37: 75000
B38: 50001 TO 75000 | C38: B | E38: 100000
B39: 75001 TO 100000 | C39: A | E39: 25000
E40: 200000
E41: 150000
H42: =_xlfn.FORMULATEXT(H6) -> =G6*30% | I42: =_xlfn.FORMULATEXT(I6) -> =(G6+H6)*40% | J42: =_xlfn.FORMULATEXT(J6) -> =IF(F6:F25="Marketing",5000,0) | K42: =_xlfn.FORMULATEXT(K6) -> =IF(F6:F25="Marketing",G6:G25+5000,G6:G25) | L42: =_xlfn.FORMULATEXT(L6) -> =G6*12% | M42: =_xlfn.FORMULATEXT(M6) -> =IF(AND(F6="Training",E6="W"),G6*40%,0) | N42: =_xlfn.FORMULATEXT(N6) -> =IF(OR(F6="Accounts",F6="Operation"),5000,0) | O42: =_xlfn.FORMULATEXT(O6) -> =IF(OR(F6="Accounts",F6="operation"),0,3500) | ... R42: =_xlfn.FORMULATEXT(R6) -> =IF(OR(AND(F6="Training",E6="w"),AND(F6="Marketing",E6="N"),AND(F6="R&D",E6="S"),AND(F6="accounts",E6="E")),G6*30%,0) | S42: CTC

Sheet QUE FOR LOGICAL FUNC
A1: Questions for logical function
A3: 1 - DA is 30% of basic.
A5: 2- HRA is 40% of (basic+DA).
A7: 3- TA is 5000 only for marketing emp.
A9: 4- PF IS 12% OF BASIC.
A11: 5- Bonus is 40% of basic only for those emp who's in training dept &
A12: staying in west region.
A14: 6-Incentive is 5000 only for those emp who's working with accounts or operation.
A16: 7-overtime is 3500 for all emp except who's working with accounts& operations.(2method)
A18: 8-p.tax (2method)ref excel for calcu.P.TAX
A20: <5000 | B20: 0
A21: >= 5000 & <=10000 | B21: 50
A22: >10000 & <=15000 | B22: 100
A23: >15000 & <=20000 | B23: 150
A24: >20000 | B24: 200
A26: 9- CCA is only for tier-1 city(delhi, mumbai, kolkata, chennai
A27: bangalore) 5000.
A30: 10-special allowance ref excel
A32: Training | B32: W | C32: 30%*BASIC | D32: 0
A33: Marketing | B33: N
A34: R&D | B34: S
A35: Accounts | B35: E
A38: 11- gross salary
A40: 12 - net salary

Sheet Freeze pane
A1: Emp Code | B1: Employee Name | C1: Address | D1: City | E1: Region | F1: Department | G1: Basic | H1: Emp Code | I1: Employee Name | J1: Address | K1: City | L1: Region | M1: Department | N1: Basic | O1: Emp Code | P1: Employee Name | Q1: Address | R1: City | S1: Region | T1: Department | U1: Basic
A2: 1 | B2: JP Kumar | C2: Andheri (W) | D2: Mumbai | E2: W | F2: Training | G2: 30000 | H2: 1 | I2: JP Kumar | J2: Andheri (W) | K2: Mumbai | L2: W | M2: Training | N2: 30000 | O2: 1 | P2: JP Kumar | Q2: Andheri (W) | R2: Mumbai | S2: W | T2: Training | U2: 30000
A3: 2 | B3: Anjali Thakur | C3: Govindpuri | D3: Delhi | E3: N | F3: Accounts | G3: 8750 | H3: 2 | I3: Anjali Thakur | J3: Govindpuri | K3: Delhi | L3: N | M3: Accounts | N3: 8750 | O3: 2 | P3: Anjali Thakur | Q3: Govindpuri | R3: Delhi | S3: N | T3: Accounts | U3: 8750
A4: 3 | B4: Priya Agarwal | C4: Sector 9 | D4: Noida | E4: N | F4: Marketing | G4: 11250 | H4: 3 | I4: Priya Agarwal | J4: Sector 9 | K4: Noida | L4: N | M4: Marketing | N4: 11250 | O4: 3 | P4: Priya Agarwal | Q4: Sector 9 | R4: Noida | S4: N | T4: Marketing | U4: 11250
A5: 4 | B5: R Vasu | C5: Egmore | D5: Chennai | E5: S | F5: R&D | G5: 10000 | H5: 4 | I5: R Vasu | J5: Egmore | K5: Chennai | L5: S | M5: R&D | N5: 10000 | O5: 4 | P5: R Vasu | Q5: Egmore | R5: Chennai | S5: S | T5: R&D | U5: 10000
A6: 5 | B6: Sanjay Gupta | C6: G K - II | D6: Delhi | E6: N | F6: Training | G6: 16250 | H6: 5 | I6: Sanjay Gupta | J6: G K - II | K6: Delhi | L6: N | M6: Training | N6: 16250 | O6: 5 | P6: Sanjay Gupta | Q6: G K - II | R6: Delhi | S6: N | T6: Training | U6: 16250
A7: 6 | B7: Jharna Biswal | C7: Link Road | D7: Cuttack | E7: E | F7: Accounts | G7: 6400 | H7: 6 | I7: Jharna Biswal | J7: Link Road | K7: Cuttack | L7: E | M7: Accounts | N7: 6400 | O7: 6 | P7: Jharna Biswal | Q7: Link Road | R7: Cuttack | S7: E | T7: Accounts | U7: 6400
A8: 7 | B8: Prakash Dutta | C8: Elgin Road | D8: Kolkata | E8: E | F8: Marketing | G8: 4500 | H8: 7 | I8: Prakash Dutta | J8: Elgin Road | K8: Kolkata | L8: E | M8: Marketing | N8: 4500 | O8: 7 | P8: Prakash Dutta | Q8: Elgin Road | R8: Kolkata | S8: E | T8: Marketing | U8: 4500
A9: 8 | B9: Manisha Guha | C9: Alipore | D9: Kolkata | E9: E | F9: R&D | G9: 6275 | H9: 8 | I9: Manisha Guha | J9: Alipore | K9: Kolkata | L9: E | M9: R&D | N9: 6275 | O9: 8 | P9: Manisha Guha | Q9: Alipore | R9: Kolkata | S9: E | T9: R&D | U9: 6275
A10: 9 | B10: Arjun Jain | C10: MG Road | D10: Mumbai | E10: W | F10: Training | G10: 6250 | H10: 9 | I10: Arjun Jain | J10: MG Road | K10: Mumbai | L10: W | M10: Training | N10: 6250 | O10: 9 | P10: Arjun Jain | Q10: MG Road | R10: Mumbai | S10: W | T10: Training | U10: 6250
A11: 10 | B11: Arjun Kapoor | C11: Kormangala | D11: Bangalore | E11: S | F11: Accounts | G11: 8750 | H11: 10 | I11: Arjun Kapoor | J11: Kormangala | K11: Bangalore | L11: S | M11: Accounts | N11: 8750 | O11: 10 | P11: Arjun Kapoor | Q11: Kormangala | R11: Bangalore | S11: S | T11: Accounts | U11: 8750
A12: 11 | B12: Abrar | C12: Jayanagar | D12: Bangalore | E12: S | F12: Marketing | G12: 11250 | H12: 11 | I12: Abrar | J12: Jayanagar | K12: Bangalore | L12: S | M12: Marketing | N12: 11250 | O12: 11 | P12: Abrar | Q12: Jayanagar | R12: Bangalore | S12: S | T12: Marketing | U12: 11250
A13: 12 | B13: Shahid Khan | C13: M.G Road | D13: Mangalore | E13: S | F13: R&D | G13: 10000 | H13: 12 | I13: Shahid Khan | J13: M.G Road | K13: Mangalore | L13: S | M13: R&D | N13: 10000 | O13: 12 | P13: Shahid Khan | Q13: M.G Road | R13: Mangalore | S13: S | T13: R&D | U13: 10000
... A41: 20 | B41: Manish Grover | C41: L L R Road | D41: Noida | E41: N | F41: Training | G41: 20000 | H41: 20 | I41: Manish Grover | J41: L L R Road | K41: Noida | L41: N | M41: Training | N41: 20000 | O41: 20 | P41: Manish Grover | Q41: L L R Road | R41: Noida | S41: N | T41: Training | U41: 20000

Sheet Conditional formatting
M2: =_xlfn.FORMULATEXT(M4) -> =I4>80000
B3: Emp Code | C3: Employee Name | D3: Address | E3: City | F3: Region | G3: Department | H3: Basic | I3: Basic | J3: DOJ | K3: DOB | L3: Age
B4: 1 | C4: JP Kumar | D4: Andheri (W) | E4: Mumbai | F4: W | G4: Training | H4: 30000 | I4: 30000 | J4: 44927 | K4: 32710 | L4: =INT(YEARFRAC(K4,TODAY())) -> 37 | M4: =I4>80000 -> FALSE
B5: 2 | C5: Anjali Thakur | D5: Govindpuri | E5: Delhi | F5: S | G5: Accounts 1 | H5: 8750 | I5: 8750 | J5: 45604 | K5: 23573 | L5: =INT(YEARFRAC(K5,TODAY())) -> 62 | M5: =I5>80000 -> FALSE
B6: 3 | C6: Priya Agarwal | D6: Sector 9 | E6: Noida | F6: N | G6: Marketing | H6: 11250 | I6: 11250 | J6: 45634 | K6: 33137 | L6: =INT(YEARFRAC(K6,TODAY())) -> 35 | M6: =I6>80000 -> FALSE
B7: 4 | C7: R Vasu | D7: Egmore | E7: Chennai | F7: S | G7: R&D | H7: 10000 | I7: 10000 | J7: 45628 | K7: 33429 | L7: =INT(YEARFRAC(K7,TODAY())) -> 35 | M7: =I7>80000 -> FALSE
B8: 5 | C8: Sanjay Gupta | D8: G K - II | E8: Delhi | F8: E | G8: Training | H8: 16250 | I8: 16250 | J8: 45200 | K8: 31026 | L8: =INT(YEARFRAC(K8,TODAY())) -> 41 | M8: =I8>80000 -> FALSE
B9: 6 | C9: Jharna Biswal | D9: Link Road | E9: Delhi | F9: E | G9: Accounts 1 | H9: 6400 | I9: 6400 | J9: 45614 | K9: 31422 | L9: =INT(YEARFRAC(K9,TODAY())) -> 40 | M9: =I9>80000 -> FALSE
B10: 7 | C10: Prakash Dutta | D10: Elgin Road | E10: Kolkata | F10: E | G10: Marketing | H10: 4500 | I10: 4500 | J10: 45631 | K10: 35043 | L10: =INT(YEARFRAC(K10,TODAY())) -> 30 | M10: =I10>80000 -> FALSE
B11: 8 | C11: Manisha Guha | D11: Alipore | E11: Kolkata | F11: E | G11: R&D | H11: 6275 | I11: 6275 | J11: 45601 | K11: 33228 | L11: =INT(YEARFRAC(K11,TODAY())) -> 35 | M11: =I11>80000 -> FALSE
B12: 9 | C12: Arjun Jain | D12: MG Road | E12: Mumbai | F12: W | G12: Training | H12: 50000 | I12: 50000 | J12: 45200 | K12: 37976 | L12: =INT(YEARFRAC(K12,TODAY())) -> 22 | M12: =I12>80000 -> FALSE
B13: 10 | C13: Arjun Kapoor | D13: Kormangala | E13: Delhi | F13: S | G13: Accounts 1 | H13: 8750 | I13: 8750 | J13: 45200 | K13: 36577 | L13: =INT(YEARFRAC(K13,TODAY())) -> 26 | M13: =I13>80000 -> FALSE
B14: 11 | C14: Abrar | D14: Jayanagar | E14: Bangalore | F14: S | G14: Marketing | H14: 11250 | I14: 11250 | J14: 45634 | K14: 33429 | L14: =INT(YEARFRAC(K14,TODAY())) -> 35 | M14: =I14>80000 -> FALSE
B15: 12 | C15: Shahid Khan | D15: M.G Road | E15: Mangalore | F15: S | G15: R&D | H15: 10000 | I15: 10000 | J15: 45634 | K15: 34714 | L15: =INT(YEARFRAC(K15,TODAY())) -> 31 | M15: =I15>80000 -> FALSE
... B23: 20 | C23: Manish Grover | D23: L L R Road | E23: Noida | F23: N | G23: Training | H23: 100000 | I23: 100000 | J23: 45697 | K23: 23451 | L23: =INT(YEARFRAC(K23,TODAY())) -> 62 | M23: =I23>80000 -> TRUE
C30: Basic more than 100000
C31: Basic Less than 60000
C32: Between 5000 to 30000
C33: Employee staying in mumbai
C34: Highlight cell where text contain accounts 1
C37: Formulas
C38: ISEVEN
C39: ISODD
C40: WEEKEND JOINERS
C41: Region wise data selection

Sheet Sorting
A1: CONDITIONAL FORMATTING, SORT & FILTER
R4: Sorting by order
R5: Sorting by cell color
R6: Sorting by font color
B7: Emp Code | C7: Employee Name | D7: Address | E7: City | F7: Region | G7: Department | H7: Basic | I7: DOJ | J7: DOB | K7: AGE | R7: Sorting by icon
B8: 13 | C8: Anupam Mishra | D8: Govindpuri | E8: Mysore | F8: S | G8: Training | H8: 100000 | I8: 44941 | J8: 33075 | K8: =INT(YEARFRAC(J8,TODAY())) -> 36 | R8: Muliti sorting
B9: 6 | C9: Abrar | D9: Jayanagar | E9: Bangalore | F9: S | G9: Marketing | H9: 11250 | I9: 45634 | J9: 33429 | K9: =INT(YEARFRAC(J9,TODAY())) -> 35 | R9: Case sensitive
B10: 4 | C10: R Vasu | D10: Egmore | E10: Chennai | F10: S | G10: R&D | H10: 10000 | I10: 45628 | J10: 33429 | K10: =INT(YEARFRAC(J10,TODAY())) -> 35 | R10: Custum sort
B11: 7 | C11: Shahid Khan | D11: M.G Road | E11: Mangalore | F11: S | G11: R&D | H11: 10000 | I11: 45634 | J11: 34714 | K11: =INT(YEARFRAC(J11,TODAY())) -> 31
B12: 3 | C12: Anjali Thakur | D12: Govindpuri | E12: Delhi | F12: S | G12: Accounts | H12: 8750 | I12: 45604 | J12: 29417 | K12: =INT(YEARFRAC(J12,TODAY())) -> 46
B13: 5 | C13: Arjun Kapoor | D13: Kormangala | E13: Bangalore | F13: S | G13: Accounts | H13: 8750 | I13: 45200 | J13: 36577 | K13: =INT(YEARFRAC(J13,TODAY())) -> 26
B14: 8 | C14: Ashwini | D14: Sector 9 | E14: Mangalore | F14: S | G14: Accounts | H14: 6400 | I14: 45614 | J14: 33981 | K14: =INT(YEARFRAC(J14,TODAY())) -> 33
B15: 9 | C15: Sukanya Reddy | D15: Alipore | E15: Mangalore | F15: S | G15: R&D | H15: 6275 | I15: 45611 | J15: 29417 | K15: =INT(YEARFRAC(J15,TODAY())) -> 46
B16: 1 | C16: Satish Puri | D16: Andheri (W) | E16: Mumbai | F16: W | G16: Operation | H16: 70000 | I16: 44927 | J16: 33981 | K16: =INT(YEARFRAC(J16,TODAY())) -> 33
B17: 12 | C17: Arjun Jain | D17: MG Road | E17: Mumbai | F17: W | G17: Training | H17: 50000 | I17: 45200 | J17: 37976 | K17: =INT(YEARFRAC(J17,TODAY())) -> 22
B18: 11 | C18: JP Kumar | D18: Andheri (W) | E18: Mumbai | F18: W | G18: Training | H18: 30000 | I18: 44927 | J18: 32710 | K18: =INT(YEARFRAC(J18,TODAY())) -> 37
B19: 14 | C19: Akram Khan | D19: S P B Road | E19: Pune | F19: W | G19: Operation | H19: 11250 | I19: 45611 | J19: 30147 | K19: =INT(YEARFRAC(J19,TODAY())) -> 44
B20: 20 | C20: Manisha Guha | D20: Alipore | E20: Kolkata | F20: E | G20: R&D | H20: 6275 | I20: 45601 | J20: 33228 | K20: =INT(YEARFRAC(J20,TODAY())) -> 35
B21: 19 | C21: Prakash Dutta | D21: Elgin Road | E21: Kolkata | F21: E | G21: Marketing | H21: 4500 | I21: 45631 | J21: 35043 | K21: =INT(YEARFRAC(J21,TODAY())) -> 30
B22: 2 | C22: Manish Grover | D22: L L R Road | E22: Noida | F22: N | G22: Training | H22: 100000 | I22: 45635 | J22: 30025 | K22: =INT(YEARFRAC(J22,TODAY())) -> 44
... B27: 10 | C27: Anjum Chopra | D27: Andheri (W) | E27: Mumbai | F27: w | G27: R&D | H27: 8750 | I27: 45614 | J27: 32710 | K27: =INT(YEARFRAC(J27,TODAY())) -> 37

Sheet Sorting h
A1: Emp Code | B1: 13 | C1: 2 | D1: 1 | E1: 12 | F1: 11 | G1: 17 | H1: 16 | I1: 6 | J1: 14 | K1: 15 | L1: 4 | M1: 7 | N1: 3 | O1: 5 | P1: 10 | Q1: 8 | R1: 18 | S1: 9 | T1: 20 | U1: 19
A2: Employee Name | B2: Anupam Mishra | C2: Manish Grover | D2: Satish Puri | E2: Arjun Jain | F2: JP Kumar | G2: Prateek Babbar | H2: Sanjay Gupta | I2: Abrar | J2: Akram Khan | K2: Priya Agarwal | L2: R Vasu | M2: Shahid Khan | N2: Anjali Thakur | O2: Arjun Kapoor | P2: Anjum Chopra | Q2: Ashwini | R2: Jharna Biswal | S2: Sukanya Reddy | T2: Manisha Guha | U2: Prakash Dutta
A3: Address | B3: Govindpuri | C3: L L R Road | D3: Andheri (W) | E3: MG Road | F3: Andheri (W) | G3: North Road | H3: G K - II | I3: Jayanagar | J3: S P B Road | K3: Sector 9 | L3: Egmore | M3: M.G Road | N3: Govindpuri | O3: Kormangala | P3: Andheri (W) | Q3: Sector 9 | R3: Link Road | S3: Alipore | T3: Alipore | U3: Elgin Road
A4: City | B4: Mysore | C4: Noida | D4: Mumbai | E4: Mumbai | F4: Mumbai | G4: Delhi | H4: Delhi | I4: Bangalore | J4: Pune | K4: Noida | L4: Chennai | M4: Mangalore | N4: Delhi | O4: Bangalore | P4: Mumbai | Q4: Mangalore | R4: Cuttack | S4: Mangalore | T4: Kolkata | U4: Kolkata
A5: Region | B5: S | C5: N | D5: W | E5: W | F5: W | G5: N | H5: n | I5: S | J5: W | K5: n | L5: S | M5: S | N5: S | O5: S | P5: w | Q5: S | R5: e | S5: S | T5: E | U5: E
A6: Department | B6: Training | C6: Training | D6: Operation | E6: Training | F6: Training | G6: Marketing | H6: Training | I6: Marketing | J6: Operation | K6: Marketing | L6: R&D | M6: R&D | N6: Accounts | O6: Accounts | P6: R&D | Q6: Accounts | R6: Accounts | S6: R&D | T6: R&D | U6: Marketing
A7: Basic | B7: 100000 | C7: 100000 | D7: 70000 | E7: 50000 | F7: 30000 | G7: 24000 | H7: 16250 | I7: 11250 | J7: 11250 | K7: 11250 | L7: 10000 | M7: 10000 | N7: 8750 | O7: 8750 | P7: 8750 | Q7: 6400 | R7: 6400 | S7: 6275 | T7: 6275 | U7: 4500
A8: DOJ | B8: 44941 | C8: 45635 | D8: 44927 | E8: 45200 | F8: 44927 | G8: 44944 | H8: 45200 | I8: 45634 | J8: 45611 | K8: 45634 | L8: 45628 | M8: 45634 | N8: 45604 | O8: 45200 | P8: 45614 | Q8: 45614 | R8: 45614 | S8: 45611 | T8: 45601 | U8: 45631
A9: DOB | B9: 33075 | C9: 30025 | D9: 33981 | E9: 37976 | F9: 32710 | G9: 30965 | H9: 31026 | I9: 33429 | J9: 30147 | K9: 33137 | L9: 33429 | M9: 34714 | N9: 29417 | O9: 36577 | P9: 32710 | Q9: 33981 | R9: 31422 | S9: 29417 | T9: 33228 | U9: 35043
A10: AGE | B10: =INT(YEARFRAC(B9,TODAY())) -> 36 | C10: =INT(YEARFRAC(C9,TODAY())) -> 44 | D10: =INT(YEARFRAC(D9,TODAY())) -> 33 | E10: =INT(YEARFRAC(E9,TODAY())) -> 22 | F10: =INT(YEARFRAC(F9,TODAY())) -> 37 | G10: =INT(YEARFRAC(G9,TODAY())) -> 41 | H10: =INT(YEARFRAC(H9,TODAY())) -> 41 | I10: =INT(YEARFRAC(I9,TODAY())) -> 35 | ... U10: =INT(YEARFRAC(U9,TODAY())) -> 30

Sheet Filter
A1: CONDITIONAL FORMATTING, SORT & FILTER
A3: Emp Code | B3: Employee Name | C3: Address | D3: City | E3: Region | F3: Department | G3: Basic | H3: DOJ | I3: DOB | J3: AGE | N3: CITY | O3: Department | Q3: Number filter
A4: 11 | B4: Abrar | C4: Jayanagar | D4: Bangalore | E4: S | F4: Marketing | G4: 11250 | H4: 45634 | I4: 33429 | J4: =INT(YEARFRAC(I4,TODAY())) -> 35 | N4: Mysore | O4: Training | Q4: TEXT filter
A5: 19 | B5: Akram Khan | C5: S P B Road | D5: Pune | E5: W | F5: Operation | G5: 11250 | H5: 45611 | I5: 30147 | J5: =INT(YEARFRAC(I5,TODAY())) -> 44 | N5: Mumbai | O5: Account | Q5: Date Filter
A6: 2 | B6: Anjali Thakur | C6: Govindpuri | D6: Delhi | E6: S | F6: Accounts | G6: 8750 | H6: 45604 | I6: 29417 | J6: =INT(YEARFRAC(I6,TODAY())) -> 46 | Q6: Advanced filter
A7: 18 | B7: Anjum Chopra | C7: Andheri (W) | D7: Mumbai | E7: w | F7: R&D | G7: 8750 | H7: 45614 | I7: 32710 | J7: =INT(YEARFRAC(I7,TODAY())) -> 37 | Q7: Wild Cards
A8: 13 | B8: Anupam Mishra | C8: Govindpuri | D8: Mysore | E8: S | F8: Training | G8: 100000 | H8: 44941 | I8: 33075 | J8: =INT(YEARFRAC(I8,TODAY())) -> 36
A9: 9 | B9: Arjun Jain | C9: MG Road | D9: Mumbai | E9: W | F9: Training | G9: 50000 | H9: 45200 | I9: 37976 | J9: =INT(YEARFRAC(I9,TODAY())) -> 22 | Q9: * | R9: Any number of Characters
A10: 10 | B10: Arjun Kapoor | C10: Kormangala | D10: Bangalore | E10: S | F10: Accounts | G10: 8750 | H10: 45200 | I10: 36577 | J10: =INT(YEARFRAC(I10,TODAY())) -> 26 | Q10: ? | R10: only one characters
A11: 14 | B11: Ashwini | C11: Sector 9 | D11: Mangalore | E11: S | F11: Accounts | G11: 6400 | H11: 45614 | I11: 33981 | J11: =INT(YEARFRAC(I11,TODAY())) -> 33 | Q11: Filter By color
A12: 6 | B12: Jharna Biswal | C12: Link Road | D12: Cuttack | E12: E | F12: Accounts | G12: 6400 | H12: 45614 | I12: 31422 | J12: =INT(YEARFRAC(I12,TODAY())) -> 40
A13: 1 | B13: JP Kumar | C13: Andheri (W) | D13: Mumbai | E13: W | F13: Training | G13: 30000 | H13: 44927 | I13: 32710 | J13: =INT(YEARFRAC(I13,TODAY())) -> 37
A14: 20 | B14: Manish Grover | C14: L L R Road | D14: Noida | E14: N | F14: Training | G14: 100000 | H14: 45635 | I14: 30025 | J14: =INT(YEARFRAC(I14,TODAY())) -> 44
A15: 8 | B15: Manisha Guha | C15: Alipore | D15: Kolkata | E15: E | F15: R&D | G15: 6275 | H15: 45601 | I15: 33228 | J15: =INT(YEARFRAC(I15,TODAY())) -> 35
A16: 7 | B16: Prakash Dutta | C16: Elgin Road | D16: Kolkata | E16: E | F16: Marketing | G16: 4500 | H16: 45631 | I16: 35043 | J16: =INT(YEARFRAC(I16,TODAY())) -> 30
A17: 15 | B17: Prateek Babbar | C17: North Road | D17: Delhi | E17: N | F17: Marketing | G17: 24000 | H17: 44944 | I17: 30965 | J17: =INT(YEARFRAC(I17,TODAY())) -> 41
A18: 3 | B18: Priya Agarwal | C18: Sector 9 | D18: Noida | E18: N | F18: Marketing | G18: 11250 | H18: 45634 | I18: 33137 | J18: =INT(YEARFRAC(I18,TODAY())) -> 35
A19: 4 | B19: R Vasu | C19: Egmore | D19: Chennai | E19: S | F19: R&D | G19: 10000 | H19: 45628 | I19: 33429 | J19: =INT(YEARFRAC(I19,TODAY())) -> 35
A20: 5 | B20: Sanjay Gupta | C20: G K - II | D20: Delhi | E20: N | F20: Training | G20: 16250 | H20: 45200 | I20: 31026 | J20: =INT(YEARFRAC(I20,TODAY())) -> 41
A21: 17 | B21: Satish Puri | C21: Andheri (W) | D21: Mumbai | E21: W | F21: Operation | G21: 70000 | H21: 44927 | I21: 33981 | J21: =INT(YEARFRAC(I21,TODAY())) -> 33
A22: 12 | B22: Shahid Khan | C22: M.G Road | D22: Mangalore | E22: S | F22: R&D | G22: 10000 | H22: 45634 | I22: 34714 | J22: =INT(YEARFRAC(I22,TODAY())) -> 31
A23: 16 | B23: Sukanya Reddy | C23: Alipore | D23: Mangalore | E23: S | F23: R&D | G23: 6275 | H23: 45611 | I23: 29417 | J23: =INT(YEARFRAC(I23,TODAY())) -> 46
A27: Emp Code | B27: Employee Name | C27: Address | D27: City | E27: Region | F27: Department | G27: Basic | H27: DOJ | I27: DOB | J27: AGE
A28: 2 | B28: Anjali Thakur | C28: Govindpuri | D28: Delhi | E28: S | F28: Accounts | G28: 8750 | H28: 45604 | I28: 29417 | J28: 45
A29: 13 | B29: Anupam Mishra | C29: Govindpuri | D29: Mysore | E29: S | F29: Training | G29: 100000 | H29: 44941 | I29: 33075 | J29: 35
A30: 9 | B30: Arjun Jain | C30: MG Road | D30: Mumbai | E30: W | F30: Training | G30: 50000 | H30: 45200 | I30: 37976 | J30: 22
A31: 10 | B31: Arjun Kapoor | C31: Kormangala | D31: Bangalore | E31: S | F31: Accounts | G31: 8750 | H31: 45200 | I31: 36577 | J31: 26
A32: 14 | B32: Ashwini | C32: Sector 9 | D32: Mangalore | E32: S | F32: Accounts | G32: 6400 | H32: 45614 | I32: 33981 | J32: 33
A33: 6 | B33: Jharna Biswal | C33: Link Road | D33: Cuttack | E33: E | F33: Accounts | G33: 6400 | H33: 45614 | I33: 31422 | J33: 40
A34: 1 | B34: JP Kumar | C34: Andheri (W) | D34: Mumbai | E34: W | F34: Training | G34: 30000 | H34: 44927 | I34: 32710 | J34: 36
A35: 20 | B35: Manish Grover | C35: L L R Road | D35: Noida | E35: N | F35: Training | G35: 100000 | H35: 45635 | I35: 30025 | J35: 44
A36: 5 | B36: Sanjay Gupta | C36: G K - II | D36: Delhi | E36: N | F36: Training | G36: 16250 | H36: 45200 | I36: 31026 | J36: 41
A40: Emp Code | B40: Employee Name | C40: Address | D40: City | E40: Region | F40: Department | G40: Basic | H40: DOJ | I40: DOB | J40: AGE
A41: 18 | B41: Anjum Chopra | C41: Andheri (W) | D41: Mumbai | E41: w | F41: R&D | G41: 8750 | H41: 45614 | I41: 32710 | J41: 36
A42: 13 | B42: Anupam Mishra | C42: Govindpuri | D42: Mysore | E42: S | F42: Training | G42: 100000 | H42: 44941 | I42: 33075 | J42: 35
A43: 9 | B43: Arjun Jain | C43: MG Road | D43: Mumbai | E43: W | F43: Training | G43: 50000 | H43: 45200 | I43: 37976 | J43: 22
A44: 1 | B44: JP Kumar | C44: Andheri (W) | D44: Mumbai | E44: W | F44: Training | G44: 30000 | H44: 44927 | I44: 32710 | J44: 36
A45: 17 | B45: Satish Puri | C45: Andheri (W) | D45: Mumbai | E45: W | F45: Operation | G45: 70000 | H45: 44927 | I45: 33981 | J45: 33

Sheet Filter with diff
A1: Emp Code | B1: Employee Name | C1: Address | D1: City | E1: Region | F1: Department | G1: Basic | H1: DOJ | I1: DOB | J1: AGE
A2: 18 | B2: Anjum Chopra | C2: Andheri (W) | D2: Mumbai | E2: w | F2: R&D | G2: 8750 | H2: 45614 | I2: 32710 | J2: 36
A3: 13 | B3: Anupam Mishra | C3: Govindpuri | D3: Mysore | E3: S | F3: Training | G3: 100000 | H3: 44941 | I3: 33075 | J3: 35
A4: 9 | B4: Arjun Jain | C4: MG Road | D4: Mumbai | E4: W | F4: Training | G4: 50000 | H4: 45200 | I4: 37976 | J4: 22
A5: 1 | B5: JP Kumar | C5: Andheri (W) | D5: Mumbai | E5: W | F5: Training | G5: 30000 | H5: 44927 | I5: 32710 | J5: 36
A6: 17 | B6: Satish Puri | C6: Andheri (W) | D6: Mumbai | E6: W | F6: Operation | G6: 70000 | H6: 44927 | I6: 33981 | J6: 33

Sheet Lookup 
A1: LOOKUP FUNCTIONS
L2: =_xlfn.FORMULATEXT(L5) -> =LOOKUP(M5,B4:B23,A4:A23) | M2: =_xlfn.FORMULATEXT(M5) -> #N/A | N2: =_xlfn.FORMULATEXT(N5) -> =LOOKUP(M5,B4:B23,D4:D23) | O2: =_xlfn.FORMULATEXT(O5) -> =LOOKUP(M5,B4:B23,F4:F23) | P2: =_xlfn.FORMULATEXT(P5) -> =LOOKUP(M5,B4:B23,G4:G23)
A3: Emp Code | B3: NAME | C3: ADDRESS | D3: City | E3: REGION | F3: DEPT | G3: SAL | H3: DATE
A4: 1 | B4: Abrar | C4: Jayanagar | D4: Bangalore | E4: S | F4: Marketing | G4: 11250 | H4: 45634 | L4: Emp Code | M4: NAME | N4: City | O4: Dept | P4: Sal
A5: 2 | B5: Akram Khan | C5: S P B Road | D5: Pune | E5: W | F5: Operation | G5: 11250 | H5: 45611 | L5: =LOOKUP(M5,B4:B23,A4:A23) -> 15 | M5: Priya Agarwal | N5: =LOOKUP(M5,B4:B23,D4:D23) -> Noida | O5: =LOOKUP(M5,B4:B23,F4:F23) -> Marketing | P5: =LOOKUP(M5,B4:B23,G4:G23) -> 11250
A6: 3 | B6: Anjali Thakur | C6: Govindpuri | D6: Delhi | E6: S | F6: Accounts | G6: 8750 | H6: 45604 | L6: =LOOKUP(M6,B5:B24,A5:A24) -> 16 | M6: R Vasu | N6: =LOOKUP(M6,B5:B24,D5:D24) -> Chennai | O6: =LOOKUP(M6,B5:B24,F5:F24) -> R&D | P6: =LOOKUP(M6,B5:B24,G5:G24) -> 10000
A7: 4 | B7: Anjum Chopra | C7: Andheri (W) | D7: Mumbai | E7: W | F7: R&D | G7: 8750 | H7: 45614 | L7: =LOOKUP(M7,B6:B25,A6:A25) -> 8 | M7: Ashwini | N7: =LOOKUP(M7,B6:B25,D6:D25) -> Mangalore | O7: =LOOKUP(M7,B6:B25,F6:F25) -> Accounts | P7: =LOOKUP(M7,B6:B25,G6:G25) -> 6400
